<?xml version="1.0" ?>
<!-- =================================================================================== -->
<!-- |    This document was autogenerated by xacro from /home/luricl/Documents/UnB/PIBIC/code/LSS-ROS2-Arms/src/lss_arm_description/urdf/lss_arm.urdf.xacro | -->
<!-- |    EDITING THIS FILE BY HAND IS NOT RECOMMENDED                                 | -->
<!-- =================================================================================== -->
<!-- URDF for LSS 4DoF/5DoF Arms -->
<robot name="lss_arm_5dof">
  <link name="world">
  </link>
  <joint name="lss_arm_joint_0" type="fixed">
    <parent link="world"/>
    <child link="lss_arm_link_0"/>
    <origin rpy="0 0 0" xyz="0 0 0"/>
  </joint>
  <link name="lss_arm_link_0">
    <visual>
      <origin rpy="0 0 0" xyz="0 0 0"/>
      <geometry>
        <mesh filename="package://lss_arm_description/meshes/visual/link_0.STL"/>
      </geometry>
      <material name="DarkGrey">
        <color rgba="0.75294 0.75294 0.75294 1.0"/>
        <diffuse>0.011764705882352941 0.011764705882352941 0.011764705882352941 1</diffuse>
        <specular>0 0 0 1</specular>
        <emissive>0 0 0 1</emissive>
      </material>
    </visual>
    <collision>
      <origin rpy="0 0 0" xyz="0 0 0"/>
      <geometry>
        <mesh filename="package://lss_arm_description/meshes/collision/link_0.STL"/>
      </geometry>
    </collision>
    <inertial>
      <origin rpy="0 0 0" xyz="-2.73691915043146E-09 0.0078496161601494 0.0255901951226594"/>
      <mass value="0.0717410813666018"/>
      <inertia ixx="3.0636904073993E-05" ixy="9.19910875697947E-11" ixz="-6.99542916495097E-14" iyy="2.37381054307842E-05" iyz="2.14417631554388E-07" izz="4.37325540149466E-05"/>
    </inertial>
  </link>
  <gazebo reference="lss_arm_link_0">
    <mu1 value="0.3"/>
    <mu2 value="0.3"/>
  </gazebo>
  <joint name="lss_arm_joint_1" type="revolute">
    <parent link="lss_arm_link_0"/>
    <child link="lss_arm_link_1"/>
    <origin rpy="1.5707963267948966 0 0" xyz="0 0 0.042699975"/>
    <axis xyz="0 1 0"/>
    <limit effort="6.5" lower="-3.141592653589793" upper="3.141592653589793" velocity="6.283"/>
    <dynamics damping="0.01" friction="3.48"/>
  </joint>
  <transmission name="lss_arm_joint_1_transmission">
    <type>transmission_interface/SimpleTransmission</type>
    <joint name="lss_arm_joint_1">
      <hardwareInterface>hardware_interface/PositionJointInterface</hardwareInterface>
    </joint>
    <actuator name="lss_arm_joint_1_actuator">
      <mechanicalReduction>1</mechanicalReduction>
    </actuator>
  </transmission>
  <gazebo reference="lss_arm_joint_1">
    <springStiffness value="0"/>
    <springReference value="0"/>
  </gazebo>
  <link name="lss_arm_link_1">
    <visual>
      <origin rpy="0 0 0" xyz="0 0 0"/>
      <geometry>
        <mesh filename="package://lss_arm_description/meshes/visual/link_1.STL"/>
      </geometry>
      <material name="DarkGrey">
        <color rgba="0.75294 0.75294 0.75294 1.0"/>
        <diffuse>0.011764705882352941 0.011764705882352941 0.011764705882352941 1</diffuse>
        <specular>0 0 0 1</specular>
        <emissive>0 0 0 1</emissive>
      </material>
    </visual>
    <collision>
      <origin rpy="0 0 0" xyz="0 0 0"/>
      <geometry>
        <mesh filename="package://lss_arm_description/meshes/collision/link_1.STL"/>
      </geometry>
    </collision>
    <inertial>
      <origin rpy="0 0 0" xyz="1.5578217768027E-09 0.0348051841749016 0.00014951767591631"/>
      <mass value="0.0628875763471834"/>
      <inertia ixx="2.20425725995968E-05" ixy="9.19935112458848E-11" ixz="1.70368679861891E-13" iyy="2.29485908974563E-05" iyz="-2.19524118186986E-07" izz="1.89578527653699E-05"/>
    </inertial>
  </link>
  <gazebo reference="lss_arm_link_1">
    <mu1 value="0.3"/>
    <mu2 value="0.3"/>
  </gazebo>
  <joint name="lss_arm_joint_2" type="revolute">
    <parent link="lss_arm_link_1"/>
    <child link="lss_arm_link_2"/>
    <origin rpy="0 0 -1.3621104667496" xyz="0 0.0588000249999991 0"/>
    <axis xyz="0 0 1"/>
    <limit effort="6.5" lower="-2.1816615649929116" upper="2.1816615649929116" velocity="6.283"/>
    <dynamics damping="0.01" friction="3.48"/>
  </joint>
  <transmission name="lss_arm_joint_2_transmission">
    <type>transmission_interface/SimpleTransmission</type>
    <joint name="lss_arm_joint_2">
      <hardwareInterface>hardware_interface/PositionJointInterface</hardwareInterface>
    </joint>
    <actuator name="lss_arm_joint_2_actuator">
      <mechanicalReduction>1</mechanicalReduction>
    </actuator>
  </transmission>
  <gazebo reference="lss_arm_joint_2">
    <springStiffness value="0"/>
    <springReference value="0"/>
  </gazebo>
  <link name="lss_arm_link_2">
    <visual>
      <origin rpy="0 0 0" xyz="0 0 0"/>
      <geometry>
        <mesh filename="package://lss_arm_description/meshes/visual/link_2.STL"/>
      </geometry>
      <material name="DarkGrey">
        <color rgba="0.75294 0.75294 0.75294 1.0"/>
        <diffuse>0.011764705882352941 0.011764705882352941 0.011764705882352941 1</diffuse>
        <specular>0 0 0 1</specular>
        <emissive>0 0 0 1</emissive>
      </material>
    </visual>
    <collision>
      <origin rpy="0 0 0" xyz="0 0 0"/>
      <geometry>
        <mesh filename="package://lss_arm_description/meshes/collision/link_2.STL"/>
      </geometry>
    </collision>
    <inertial>
      <origin rpy="0 0 0" xyz="-0.112045323028693 0.0336416089233315 0.000234166707606796"/>
      <mass value="0.0592207297890142"/>
      <inertia ixx="1.66333998725443E-05" ixy="-1.03352394963547E-06" ixz="-4.43274108116386E-08" iyy="1.1971383214163E-05" iyz="-2.15005479062966E-07" izz="1.41577057658295E-05"/>
    </inertial>
  </link>
  <gazebo reference="lss_arm_link_2">
    <mu1 value="0.3"/>
    <mu2 value="0.3"/>
  </gazebo>
  <joint name="lss_arm_joint_3" type="revolute">
    <parent link="lss_arm_link_2"/>
    <child link="lss_arm_link_3"/>
    <origin rpy="0 0 1.02985068022995" xyz="-0.12954806230389 0.0533975613048809 0"/>
    <axis xyz="0 0 1"/>
    <limit effort="6.5" lower="-1.9198621771937625" upper="1.5707963267948966" velocity="6.283"/>
    <dynamics damping="0.01" friction="3.48"/>
  </joint>
  <transmission name="lss_arm_joint_3_transmission">
    <type>transmission_interface/SimpleTransmission</type>
    <joint name="lss_arm_joint_3">
      <hardwareInterface>hardware_interface/PositionJointInterface</hardwareInterface>
    </joint>
    <actuator name="lss_arm_joint_3_actuator">
      <mechanicalReduction>1</mechanicalReduction>
    </actuator>
  </transmission>
  <gazebo reference="lss_arm_joint_3">
    <springStiffness value="0"/>
    <springReference value="0"/>
  </gazebo>
  <link name="lss_arm_link_3">
    <visual>
      <origin rpy="0 0 0" xyz="0 0 0"/>
      <geometry>
        <mesh filename="package://lss_arm_description/meshes/visual/link_3.STL"/>
      </geometry>
      <material name="DarkGrey">
        <color rgba="0.75294 0.75294 0.75294 1.0"/>
        <diffuse>0.011764705882352941 0.011764705882352941 0.011764705882352941 1</diffuse>
        <specular>0 0 0 1</specular>
        <emissive>0 0 0 1</emissive>
      </material>
    </visual>
    <collision>
      <origin rpy="0 0 0" xyz="0 0 0"/>
      <geometry>
        <mesh filename="package://lss_arm_description/meshes/collision/link_3.STL"/>
      </geometry>
    </collision>
    <inertial>
      <origin rpy="0 0 0" xyz="0.119623138465818 0.0411506770766876 0.000345214465821365"/>
      <mass value="0.0601490353124708"/>
      <inertia ixx="1.1113660383281E-05" ixy="-2.67466932607218E-06" ixz="2.01605698642722E-07" iyy="1.79419649434231E-05" iyz="-6.9564477599757E-08" izz="1.45807099366603E-05"/>
    </inertial>
  </link>
  <gazebo reference="lss_arm_link_3">
    <mu1 value="0.3"/>
    <mu2 value="0.3"/>
  </gazebo>
  <ros2_control name="lss_arm_system" type="system">
    <hardware>
      <plugin>ign_ros2_control/IgnitionSystem</plugin>
    </hardware>
    <joint name="lss_arm_joint_1">
      <param name="initial_position">0.0</param>
      <command_interface name="position">
        <param name="min">-3.14</param>
        <param name="max">3.14</param>
      </command_interface>
      <state_interface name="position"/>
      <state_interface name="velocity"/>
      <state_interface name="effort"/>
    </joint>
    <joint name="lss_arm_joint_2">
      <param name="initial_position">1.7</param>
      <command_interface name="position">
        <param name="min">-2.18</param>
        <param name="max">2.18</param>
      </command_interface>
      <state_interface name="position"/>
      <state_interface name="velocity"/>
      <state_interface name="effort"/>
    </joint>
    <joint name="lss_arm_joint_3">
      <param name="initial_position">-0.7</param>
      <command_interface name="position">
        <param name="min">-1.92</param>
        <param name="max">1.57</param>
      </command_interface>
      <state_interface name="position"/>
      <state_interface name="velocity"/>
      <state_interface name="effort"/>
    </joint>
    <joint name="lss_arm_joint_4">
      <param name="initial_position">-1.7</param>
      <command_interface name="position">
        <param name="min">-2</param>
        <param name="max">2</param>
      </command_interface>
      <state_interface name="position"/>
      <state_interface name="velocity"/>
      <state_interface name="effort"/>
    </joint>
    <joint name="lss_arm_joint_5">
      <param name="initial_position">0.0</param>
      <command_interface name="position">
        <param name="min">0</param>
        <param name="max">0.8</param>
      </command_interface>
      <state_interface name="position"/>
      <state_interface name="velocity"/>
      <state_interface name="effort"/>
    </joint>
    <joint name="lss_arm_joint_6">
      <param name="initial_position">0.0</param>
      <command_interface name="position">
        <param name="min">-3.14</param>
        <param name="max">3.14</param>
      </command_interface>
      <state_interface name="position"/>
      <state_interface name="velocity"/>
      <state_interface name="effort"/>
    </joint>
  </ros2_control>
  <joint name="lss_arm_joint_4" type="revolute">
    <parent link="lss_arm_link_3"/>
    <child link="lss_arm_link_4"/>
    <origin rpy="0 0 0.332259786519651" xyz="0.15427 0.053233 0"/>
    <axis xyz="0 0 1"/>
    <limit effort="6.5" lower="-2.443460952792061" upper="2.443460952792061" velocity="6.283"/>
    <dynamics damping="0.01" friction="3.48"/>
  </joint>
  <transmission name="lss_arm_joint_4_transmission">
    <type>transmission_interface/SimpleTransmission</type>
    <joint name="lss_arm_joint_4">
      <hardwareInterface>hardware_interface/PositionJointInterface</hardwareInterface>
    </joint>
    <actuator name="lss_arm_joint_4_actuator">
      <mechanicalReduction>1</mechanicalReduction>
    </actuator>
  </transmission>
  <gazebo reference="lss_arm_joint_4">
    <springStiffness value="0"/>
    <springReference value="0"/>
  </gazebo>
  <link name="lss_arm_link_4">
    <visual>
      <origin rpy="0 0 0" xyz="0 0 0"/>
      <geometry>
        <mesh filename="package://lss_arm_description/meshes/visual/link_4_5dof.STL"/>
      </geometry>
      <material name="DarkGrey">
        <color rgba="0.75294 0.75294 0.75294 1.0"/>
        <diffuse>0.011764705882352941 0.011764705882352941 0.011764705882352941 1</diffuse>
        <specular>0 0 0 1</specular>
        <emissive>0 0 0 1</emissive>
      </material>
    </visual>
    <collision>
      <origin rpy="0 0 0" xyz="0 0 0"/>
      <geometry>
        <mesh filename="package://lss_arm_description/meshes/collision/link_4_5dof.STL"/>
      </geometry>
    </collision>
    <inertial>
      <origin rpy="0 0 0" xyz="0.041227 -1.5305E-06 -0.010489"/>
      <mass value="0.051733"/>
      <inertia ixx="1.3345E-05" ixy="2.5814E-10" ixz="-1.8101E-07" iyy="1.6468E-05" iyz="-7.6602E-10" izz="8.1683E-06"/>
    </inertial>
  </link>
  <gazebo reference="lss_arm_link_4">
    <mu1 value="0.3"/>
    <mu2 value="0.3"/>
  </gazebo>
  <joint name="lss_arm_joint_6" type="revolute">
    <parent link="lss_arm_link_4"/>
    <child link="lss_arm_link_5"/>
    <origin rpy="0 0 0" xyz="0.060452 0.0083301 0.00016494"/>
    <axis xyz="1 0 0"/>
    <limit effort="6.5" lower="-3.141592653589793" upper="3.141592653589793" velocity="6.283"/>
    <dynamics damping="0.01" friction="3.48"/>
  </joint>
  <transmission name="lss_arm_joint_6_transmission">
    <type>transmission_interface/SimpleTransmission</type>
    <joint name="lss_arm_joint_6">
      <hardwareInterface>hardware_interface/PositionJointInterface</hardwareInterface>
    </joint>
    <actuator name="lss_arm_joint_6_actuator">
      <mechanicalReduction>1</mechanicalReduction>
    </actuator>
  </transmission>
  <gazebo reference="lss_arm_joint_6">
    <springStiffness value="0"/>
    <springReference value="0"/>
  </gazebo>
  <link name="lss_arm_link_5">
    <visual>
      <origin rpy="0 0 0" xyz="0 0 0"/>
      <geometry>
        <mesh filename="package://lss_arm_description/meshes/visual/link_5_5dof.STL"/>
      </geometry>
      <material name="DarkGrey">
        <color rgba="0.75294 0.75294 0.75294 1.0"/>
        <diffuse>0.011764705882352941 0.011764705882352941 0.011764705882352941 1</diffuse>
        <specular>0 0 0 1</specular>
        <emissive>0 0 0 1</emissive>
      </material>
    </visual>
    <collision>
      <origin rpy="0 0 0" xyz="0 0 0"/>
      <geometry>
        <mesh filename="package://lss_arm_description/meshes/collision/link_5_5dof.STL"/>
      </geometry>
    </collision>
    <inertial>
      <origin rpy="0 0 0" xyz="0.033089 -0.0086089 4.6839E-05"/>
      <mass value="0.050102"/>
      <inertia ixx="1.6176E-05" ixy="-9.3694E-14" ixz="9.1972E-11" iyy="1.2688E-05" iyz="2.1445E-07" izz="8.3014E-06"/>
    </inertial>
  </link>
  <gazebo reference="lss_arm_link_5">
    <mu1 value="0.3"/>
    <mu2 value="0.3"/>
  </gazebo>
  <joint name="lss_arm_joint_5" type="revolute">
    <parent link="lss_arm_link_5"/>
    <child link="lss_arm_finger_l"/>
    <origin rpy="0 0 0" xyz="0.035 -0.012 -0.0127"/>
    <axis xyz="0 1 0"/>
    <limit effort="1.45" lower="0" upper="1.5707963267948966" velocity="6.283"/>
    <dynamics damping="0.01" friction="0.4"/>
  </joint>
  <transmission name="lss_arm_joint_5_transmission">
    <type>transmission_interface/SimpleTransmission</type>
    <joint name="lss_arm_joint_5">
      <hardwareInterface>hardware_interface/PositionJointInterface</hardwareInterface>
    </joint>
    <actuator name="lss_arm_joint_5_actuator">
      <mechanicalReduction>1</mechanicalReduction>
    </actuator>
  </transmission>
  <gazebo reference="lss_arm_joint_5">
    <springStiffness value="0"/>
    <springReference value="0"/>
  </gazebo>
  <link name="lss_arm_finger_l">
    <visual>
      <origin rpy="0 0 0" xyz="0 0 0"/>
      <geometry>
        <mesh filename="package://lss_arm_description/meshes/visual/finger_l.STL"/>
      </geometry>
      <material name="DarkGrey">
        <color rgba="0.75294 0.75294 0.75294 1.0"/>
        <diffuse>0.011764705882352941 0.011764705882352941 0.011764705882352941 1</diffuse>
        <specular>0 0 0 1</specular>
        <emissive>0 0 0 1</emissive>
      </material>
    </visual>
    <collision>
      <origin rpy="0 0 0" xyz="0 0 0"/>
      <geometry>
        <mesh filename="package://lss_arm_description/meshes/collision/finger_l.STL"/>
      </geometry>
    </collision>
    <inertial>
      <origin rpy="0 0 0" xyz="0.0310712366675979 -0.0140452526813673 0.00133953163684892"/>
      <mass value="0.0152813047822834"/>
      <inertia ixx="6.12119941271843E-07" ixy="-1.61044889315886E-12" ixz="-4.41621763353496E-07" iyy="2.99804070646807E-06" iyz="-3.8879675590965E-12" izz="2.54603357212087E-06"/>
    </inertial>
  </link>
  <gazebo reference="lss_arm_finger_l">
    <mu1 value="0.3"/>
    <mu2 value="0.3"/>
  </gazebo>
  <!-- mimic_joint="${prefix}${joint_finger_1_name}" -->
  <joint name="lss_arm_joint_7" type="revolute">
    <parent link="lss_arm_link_5"/>
    <child link="lss_arm_finger_r"/>
    <origin rpy="0 0 0" xyz="0.035 -0.012 0.0127"/>
    <axis xyz="0 1 0"/>
    <limit effort="1.45" lower="-1.5707963267948966" upper="0" velocity="6.283"/>
    <dynamics damping="0.01" friction="0.4"/>
  </joint>
  <transmission name="lss_arm_joint_7_transmission">
    <type>transmission_interface/SimpleTransmission</type>
    <joint name="lss_arm_joint_7">
      <hardwareInterface>hardware_interface/PositionJointInterface</hardwareInterface>
    </joint>
    <actuator name="lss_arm_joint_7_actuator">
      <mechanicalReduction>1</mechanicalReduction>
    </actuator>
  </transmission>
  <gazebo reference="lss_arm_joint_7">
    <springStiffness value="0"/>
    <springReference value="0"/>
  </gazebo>
  <link name="lss_arm_finger_r">
    <visual>
      <origin rpy="0 0 0" xyz="0 0 0"/>
      <geometry>
        <mesh filename="package://lss_arm_description/meshes/visual/finger_r.STL"/>
      </geometry>
      <material name="DarkGrey">
        <color rgba="0.75294 0.75294 0.75294 1.0"/>
        <diffuse>0.011764705882352941 0.011764705882352941 0.011764705882352941 1</diffuse>
        <specular>0 0 0 1</specular>
        <emissive>0 0 0 1</emissive>
      </material>
    </visual>
    <collision>
      <origin rpy="0 0 0" xyz="0 0 0"/>
      <geometry>
        <mesh filename="package://lss_arm_description/meshes/collision/finger_r.STL"/>
      </geometry>
    </collision>
    <inertial>
      <origin rpy="0 0 0" xyz="0.0307726942893274 -0.0140975049159748 -0.0013266609885073"/>
      <mass value="0.0154295568992377"/>
      <inertia ixx="6.13242885883712E-07" ixy="-1.69555790218149E-12" ixz="4.41621764601781E-07" iyy="2.99899721506146E-06" iyz="4.09343888509186E-12" izz="2.54715653674288E-06"/>
    </inertial>
  </link>
  <gazebo reference="lss_arm_finger_r">
    <mu1 value="0.3"/>
    <mu2 value="0.3"/>
  </gazebo>
  <link name="lss_arm_ee">
  </link>
  <joint name="lss_arm_ee_virtual_joint" type="fixed">
    <parent link="lss_arm_link_5"/>
    <child link="lss_arm_ee"/>
    <origin rpy="0 0 0" xyz="0.095 -0.01 0"/>
  </joint>
  <gazebo>
    <plugin filename="libign_ros2_control-system.so" name="ign_ros2_control::IgnitionROS2ControlPlugin">
      <parameters>/home/luricl/Documents/UnB/PIBIC/code/LSS-ROS2-Arms/install/lss_arm_moveit/share/lss_arm_moveit/config/controllers_5dof.yaml</parameters>
    </plugin>
  </gazebo>
</robot>
